<sdf version='1.6'>
  <model name='ur5_qb'>
    <link name='base_link'>
      <pose frame=''>0 0 0.5 0 -0 0</pose>
      <inertial>
        <pose frame=''>0 0 0 0 -0 0</pose>
        <mass>4</mass>
        <inertia>
          <ixx>0.00443333</ixx>
          <ixy>0</ixy>
          <ixz>0</ixz>
          <iyy>0.00443333</iyy>
          <iyz>0</iyz>
          <izz>0.0072</izz>
        </inertia>
      </inertial>
      <collision name='base_link_collision'>
        <pose frame=''>0 0 0 0 -0 0</pose>
        <geometry>
          <mesh>
            <scale>1 1 1</scale>
            <uri>model://ur_description/meshes/ur5/collision/base.stl</uri>
          </mesh>
        </geometry>
      </collision>
      <visual name='base_link_visual'>
        <pose frame=''>0 0 0 0 -0 0</pose>
        <geometry>
          <mesh>
            <scale>1 1 1</scale>
            <uri>model://ur_description/meshes/ur5/visual/base.dae</uri>
          </mesh>
        </geometry>
      </visual>
    </link>
    <joint name='world_to_robot' type='revolute'>
      <child>base_link</child>
      <parent>world</parent>
      <axis>
        <limit>
          <lower>0</lower>
          <upper>0</upper>
        </limit>
        <dynamics>
          <damping>0</damping>
          <friction>0</friction>
          <spring_reference>0</spring_reference>
          <spring_stiffness>0</spring_stiffness>
        </dynamics>
        <use_parent_model_frame>1</use_parent_model_frame>
        <xyz>0 0 1</xyz>
      </axis>
    </joint>
    <link name='shoulder_link'>
      <pose frame=''>0 0 0.589159 0 -0 0</pose>
      <inertial>
        <pose frame=''>0 0 0 0 -0 0</pose>
        <mass>3.7</mass>
        <inertia>
          <ixx>0.0102675</ixx>
          <ixy>0</ixy>
          <ixz>0</ixz>
          <iyy>0.0102675</iyy>
          <iyz>0</iyz>
          <izz>0.00666</izz>
        </inertia>
      </inertial>
      <collision name='shoulder_link_collision'>
        <pose frame=''>0 0 0 0 -0 0</pose>
        <geometry>
          <mesh>
            <scale>1 1 1</scale>
            <uri>model://ur_description/meshes/ur5/collision/shoulder.stl</uri>
          </mesh>
        </geometry>
        <surface>
          <contact>
            <ode/>
          </contact>
          <friction>
            <ode/>
          </friction>
        </surface>
      </collision>
      <visual name='shoulder_link_visual'>
        <pose frame=''>0 0 0 0 -0 0</pose>
        <geometry>
          <mesh>
            <scale>1 1 1</scale>
            <uri>model://ur_description/meshes/ur5/visual/shoulder.dae</uri>
          </mesh>
        </geometry>
        <material>
          <script>
            <uri>__default__</uri>
            <name>__default__</name>
          </script>
        </material>
      </visual>
      <gravity>1</gravity>
      <velocity_decay/>
      <self_collide>1</self_collide>
    </link>
    <joint name='shoulder_pan_joint' type='revolute'>
      <child>shoulder_link</child>
      <parent>base_link</parent>
      <axis>
        <xyz>0 0 1</xyz>
        <limit>
          <lower>-6.28319</lower>
          <upper>6.28319</upper>
          <effort>150</effort>
          <velocity>3.15</velocity>
        </limit>
        <dynamics>
          <damping>0</damping>
          <friction>0</friction>
          <spring_reference>0</spring_reference>
          <spring_stiffness>0</spring_stiffness>
        </dynamics>
        <use_parent_model_frame>1</use_parent_model_frame>
      </axis>
    </joint>
    <link name='upper_arm_link'>
      <pose frame=''>0 0.13585 0.589159 3.14159 1.57079 3.14159</pose>
      <inertial>
        <pose frame=''>0 0 0.28 0 -0 0</pose>
        <mass>8.393</mass>
        <inertia>
          <ixx>0.226891</ixx>
          <ixy>0</ixy>
          <ixz>0</ixz>
          <iyy>0.226891</iyy>
          <iyz>0</iyz>
          <izz>0.0151074</izz>
        </inertia>
      </inertial>
      <collision name='upper_arm_link_collision'>
        <pose frame=''>0 0 0 0 -0 0</pose>
        <geometry>
          <mesh>
            <scale>1 1 1</scale>
            <uri>model://ur_description/meshes/ur5/collision/upperarm.stl</uri>
          </mesh>
        </geometry>
        <surface>
          <contact>
            <ode/>
          </contact>
          <friction>
            <ode/>
          </friction>
        </surface>
      </collision>
      <visual name='upper_arm_link_visual'>
        <pose frame=''>0 0 0 0 -0 0</pose>
        <geometry>
          <mesh>
            <scale>1 1 1</scale>
            <uri>model://ur_description/meshes/ur5/visual/upperarm.dae</uri>
          </mesh>
        </geometry>
        <material>
          <script>
            <uri>__default__</uri>
            <name>__default__</name>
          </script>
        </material>
      </visual>
      <gravity>1</gravity>
      <velocity_decay/>
      <self_collide>1</self_collide>
    </link>
    <joint name='shoulder_lift_joint' type='revolute'>
      <child>upper_arm_link</child>
      <parent>shoulder_link</parent>
      <axis>
        <xyz>0 1 0</xyz>
        <limit>
          <lower>-6.28319</lower>
          <upper>6.28319</upper>
          <effort>150</effort>
          <velocity>3.15</velocity>
        </limit>
        <dynamics>
          <damping>0</damping>
          <friction>0</friction>
          <spring_reference>0</spring_reference>
          <spring_stiffness>0</spring_stiffness>
        </dynamics>
        <use_parent_model_frame>1</use_parent_model_frame>
      </axis>
    </joint>
    <link name='forearm_link'>
      <pose frame=''>0.425 0.01615 0.589159 3.14159 1.57079 3.14159</pose>
      <inertial>
        <pose frame=''>0 0 0.196125 0 -0 0</pose>
        <mass>2.275</mass>
        <inertia>
          <ixx>0.0312168</ixx>
          <ixy>0</ixy>
          <ixz>0</ixz>
          <iyy>0.0312168</iyy>
          <iyz>0</iyz>
          <izz>0.004095</izz>
        </inertia>
      </inertial>
      <collision name='forearm_link_collision'>
        <pose frame=''>0 0 0 0 -0 0</pose>
        <geometry>
          <mesh>
            <scale>1 1 1</scale>
            <uri>model://ur_description/meshes/ur5/collision/forearm.stl</uri>
          </mesh>
        </geometry>
        <surface>
          <contact>
            <ode/>
          </contact>
          <friction>
            <ode/>
          </friction>
        </surface>
      </collision>
      <visual name='forearm_link_visual'>
        <pose frame=''>0 0 0 0 -0 0</pose>
        <geometry>
          <mesh>
            <scale>1 1 1</scale>
            <uri>model://ur_description/meshes/ur5/visual/forearm.dae</uri>
          </mesh>
        </geometry>
        <material>
          <script>
            <uri>__default__</uri>
            <name>__default__</name>
          </script>
        </material>
      </visual>
      <gravity>1</gravity>
      <velocity_decay/>
      <self_collide>1</self_collide>
    </link>
    <joint name='elbow_joint' type='revolute'>
      <child>forearm_link</child>
      <parent>upper_arm_link</parent>
      <axis>
        <xyz>0 1 0</xyz>
        <limit>
          <lower>-3.14159</lower>
          <upper>3.14159</upper>
          <effort>150</effort>
          <velocity>3.15</velocity>
        </limit>
        <dynamics>
          <damping>0</damping>
          <friction>0</friction>
          <spring_reference>0</spring_reference>
          <spring_stiffness>0</spring_stiffness>
        </dynamics>
        <use_parent_model_frame>1</use_parent_model_frame>
      </axis>
    </joint>
    <link name='wrist_1_link'>
      <pose frame=''>0.81725 0.01615 0.589159 3.14159 0 3.14159</pose>
      <inertial>
        <pose frame=''>0 0.093 0 0 -0 0</pose>
        <mass>1.219</mass>
        <inertia>
          <ixx>0.0025599</ixx>
          <ixy>0</ixy>
          <ixz>0</ixz>
          <iyy>0.0025599</iyy>
          <iyz>0</iyz>
          <izz>0.0021942</izz>
        </inertia>
      </inertial>
      <collision name='wrist_1_link_collision'>
        <pose frame=''>0 0 0 0 -0 0</pose>
        <geometry>
          <mesh>
            <scale>1 1 1</scale>
            <uri>model://ur_description/meshes/ur5/collision/wrist1.stl</uri>
          </mesh>
        </geometry>
        <surface>
          <contact>
            <ode/>
          </contact>
          <friction>
            <ode/>
          </friction>
        </surface>
      </collision>
      <visual name='wrist_1_link_visual'>
        <pose frame=''>0 0 0 0 -0 0</pose>
        <geometry>
          <mesh>
            <scale>1 1 1</scale>
            <uri>model://ur_description/meshes/ur5/visual/wrist1.dae</uri>
          </mesh>
        </geometry>
        <material>
          <script>
            <uri>__default__</uri>
            <name>__default__</name>
          </script>
        </material>
      </visual>
      <gravity>1</gravity>
      <velocity_decay/>
      <self_collide>1</self_collide>
    </link>
    <joint name='wrist_1_joint' type='revolute'>
      <child>wrist_1_link</child>
      <parent>forearm_link</parent>
      <axis>
        <xyz>0 1 0</xyz>
        <limit>
          <lower>-6.28319</lower>
          <upper>6.28319</upper>
          <effort>28</effort>
          <velocity>3.2</velocity>
        </limit>
        <dynamics>
          <damping>0</damping>
          <friction>0</friction>
          <spring_reference>0</spring_reference>
          <spring_stiffness>0</spring_stiffness>
        </dynamics>
        <use_parent_model_frame>1</use_parent_model_frame>
      </axis>
    </joint>
    <link name='wrist_2_link'>
      <pose frame=''>0.81725 0.10915 0.589159 3.14159 0 3.14159</pose>
      <inertial>
        <pose frame=''>0 0 0.09465 0 -0 0</pose>
        <mass>1.219</mass>
        <inertia>
          <ixx>0.0025599</ixx>
          <ixy>0</ixy>
          <ixz>0</ixz>
          <iyy>0.0025599</iyy>
          <iyz>0</iyz>
          <izz>0.0021942</izz>
        </inertia>
      </inertial>
      <collision name='wrist_2_link_collision'>
        <pose frame=''>0 0 0 0 -0 0</pose>
        <geometry>
          <mesh>
            <scale>1 1 1</scale>
            <uri>model://ur_description/meshes/ur5/collision/wrist2.stl</uri>
          </mesh>
        </geometry>
        <surface>
          <contact>
            <ode/>
          </contact>
          <friction>
            <ode/>
          </friction>
        </surface>
      </collision>
      <visual name='wrist_2_link_visual'>
        <pose frame=''>0 0 0 0 -0 0</pose>
        <geometry>
          <mesh>
            <scale>1 1 1</scale>
            <uri>model://ur_description/meshes/ur5/visual/wrist2.dae</uri>
          </mesh>
        </geometry>
        <material>
          <script>
            <uri>__default__</uri>
            <name>__default__</name>
          </script>
        </material>
      </visual>
      <gravity>1</gravity>
      <velocity_decay/>
      <self_collide>1</self_collide>
    </link>
    <joint name='wrist_2_joint' type='revolute'>
      <child>wrist_2_link</child>
      <parent>wrist_1_link</parent>
      <axis>
        <xyz>0 0 -1</xyz>
        <limit>
          <lower>-6.28319</lower>
          <upper>6.28319</upper>
          <effort>28</effort>
          <velocity>3.2</velocity>
        </limit>
        <dynamics>
          <damping>0</damping>
          <friction>0</friction>
          <spring_reference>0</spring_reference>
          <spring_stiffness>0</spring_stiffness>
        </dynamics>
        <use_parent_model_frame>1</use_parent_model_frame>
      </axis>
    </joint>
    <link name='wrist_3_link'>
      <pose frame=''>0.81725 0.10915 0.494509 3.14159 0 3.14159</pose>
      <inertial>
        <pose frame=''>-0.033263 0.162595 -0.002362 1.5708 -0 0</pose>
        <mass>0.6979</mass>
        <inertia>
          <ixx>0.00564227</ixx>
          <ixy>-5.17913e-05</ixy>
          <ixz>-0.00194434</ixz>
          <iyy>0.00656339</iyy>
          <iyz>-0.000138067</iyz>
          <izz>0.00155054</izz>
        </inertia>
      </inertial>
      <collision name='wrist_3_link_collision'>
        <pose frame=''>0 0 0 0 -0 0</pose>
        <geometry>
          <mesh>
            <scale>1 1 1</scale>
            <uri>model://ur_description/meshes/ur5/collision/wrist3.stl</uri>
          </mesh>
        </geometry>
        <surface>
          <contact>
            <ode/>
          </contact>
          <friction>
            <ode/>
          </friction>
        </surface>
      </collision>
      <collision name='wrist_3_link_fixed_joint_lump__ee_link_collision_1'>
        <pose frame=''>-0 0.0723 0 0 -0 1.5708</pose>
        <geometry>
          <box>
            <size>0.01 0.01 0.01</size>
          </box>
        </geometry>
        <surface>
          <contact>
            <ode/>
          </contact>
          <friction>
            <ode/>
          </friction>
        </surface>
      </collision>
      <collision name='wrist_3_link_fixed_joint_lump__qbhand_base_link_collision_2'>
        <pose frame=''>0 0.0823 0 3.14159 1.57079 -1.57079</pose>
        <geometry>
          <mesh>
            <scale>0.001 0.001 0.001</scale>
            <uri>model://qb_hand_description/meshes/flange_iso_04.stl</uri>
          </mesh>
        </geometry>
      </collision>
      <collision name='wrist_3_link_fixed_joint_lump__qbhand_palm_link_collision_3'>
        <pose frame=''>-0.0145 0.226304 -0.004385 3.14159 -1.57079 -3.14159</pose>
        <geometry>
          <mesh>
            <scale>0.001 0.001 0.001</scale>
            <uri>model://qb_hand_description/meshes/palm_pinch_l.stl</uri>
          </mesh>
        </geometry>
      </collision>
      <visual name='wrist_3_link_visual'>
        <pose frame=''>0 0 0 0 -0 0</pose>
        <geometry>
          <mesh>
            <scale>1 1 1</scale>
            <uri>model://ur_description/meshes/ur5/visual/wrist3.dae</uri>
          </mesh>
        </geometry>
        <material>
          <script>
            <uri>__default__</uri>
            <name>__default__</name>
          </script>
        </material>
      </visual>
      <visual name='wrist_3_link_fixed_joint_lump__qbhand_base_link_visual_1'>
        <pose frame=''>0 0.0823 0 3.14159 1.57079 -1.57079</pose>
        <geometry>
          <mesh>
            <scale>0.001 0.001 0.001</scale>
            <uri>model://qb_hand_description/meshes/flange_iso_04.stl</uri>
          </mesh>
        </geometry>
      </visual>
      <visual name='wrist_3_link_fixed_joint_lump__qbhand_palm_link_visual_2'>
        <pose frame=''>-0.0145 0.226304 -0.004385 3.14159 -1.57079 -3.14159</pose>
        <geometry>
          <mesh>
            <scale>0.001 0.001 0.001</scale>
            <uri>model://qb_hand_description/meshes/palm_pinch_l.stl</uri>
          </mesh>
        </geometry>
      </visual>
      <velocity_decay/>
      <gravity>1</gravity>
      <velocity_decay/>
      <self_collide>1</self_collide>
    </link>
    <joint name='wrist_3_joint' type='revolute'>
      <child>wrist_3_link</child>
      <parent>wrist_2_link</parent>
      <axis>
        <xyz>0 1 0</xyz>
        <limit>
          <lower>-6.28319</lower>
          <upper>6.28319</upper>
          <effort>28</effort>
          <velocity>3.2</velocity>
        </limit>
        <dynamics>
          <damping>0</damping>
          <friction>0</friction>
          <spring_reference>0</spring_reference>
          <spring_stiffness>0</spring_stiffness>
        </dynamics>
        <use_parent_model_frame>1</use_parent_model_frame>
      </axis>
    </joint>
    <link name='qbhand_index_knuckle_link'>
      <pose frame=''>0.817724 0.328458 0.518878 -2.89619 -1.56751 2.89699</pose>
      <inertial>
        <pose frame=''>0 0 0 0 -0 0</pose>
        <mass>0.01</mass>
        <inertia>
          <ixx>1e-06</ixx>
          <ixy>0</ixy>
          <ixz>0</ixz>
          <iyy>1e-06</iyy>
          <iyz>0</iyz>
          <izz>1e-06</izz>
        </inertia>
      </inertial>
      <collision name='qbhand_index_knuckle_link_collision'>
        <pose frame=''>0 0 0 0 -0 0</pose>
        <geometry>
          <mesh>
            <scale>0.001 0.001 0.001</scale>
            <uri>model://qb_hand_description/meshes/ph_knuckle.stl</uri>
          </mesh>
        </geometry>
      </collision>
      <visual name='qbhand_index_knuckle_link_visual'>
        <pose frame=''>0 0 0 0 -0 0</pose>
        <geometry>
          <mesh>
            <scale>0.001 0.001 0.001</scale>
            <uri>model://qb_hand_description/meshes/ph_knuckle.stl</uri>
          </mesh>
        </geometry>
      </visual>
    </link>
    <joint name='qbhand_index_knuckle_joint' type='revolute'>
      <child>qbhand_index_knuckle_link</child>
      <parent>wrist_3_link</parent>
      <axis>
        <xyz>0.999995 0.000799 0.003185</xyz>
        <limit>
          <lower>-0.524</lower>
          <upper>0.524</upper>
          <effort>100</effort>
          <velocity>100</velocity>
        </limit>
        <dynamics>
          <damping>0</damping>
          <friction>0</friction>
          <spring_reference>0</spring_reference>
          <spring_stiffness>0</spring_stiffness>
        </dynamics>
        <use_parent_model_frame>1</use_parent_model_frame>
      </axis>
    </joint>
    <link name='qbhand_index_proximal_virtual_link'>
      <pose frame=''>0.817717 0.337458 0.51887 -0.003981 1e-06 1.5716</pose>
      <inertial>
        <pose frame=''>0 0 0 0 -0 0</pose>
        <mass>0.01</mass>
        <inertia>
          <ixx>1e-08</ixx>
          <ixy>0</ixy>
          <ixz>0</ixz>
          <iyy>1e-08</iyy>
          <iyz>0</iyz>
          <izz>1e-08</izz>
        </inertia>
      </inertial>
    </link>
    <joint name='qbhand_index_proximal_joint' type='revolute'>
      <child>qbhand_index_proximal_virtual_link</child>
      <parent>qbhand_index_knuckle_link</parent>
      <axis>
        <xyz>0.003981 2e-06 -0.999992</xyz>
        <limit>
          <lower>0</lower>
          <upper>0.785</upper>
          <effort>100</effort>
          <velocity>100</velocity>
        </limit>
        <dynamics>
          <damping>0</damping>
          <friction>0</friction>
          <spring_reference>0</spring_reference>
          <spring_stiffness>0</spring_stiffness>
        </dynamics>
        <use_parent_model_frame>1</use_parent_model_frame>
      </axis>
    </joint>
    <link name='qbhand_index_proximal_link'>
      <pose frame=''>0.817706 0.350458 0.51887 -0.003981 1e-06 1.5716</pose>
      <inertial>
        <pose frame=''>0 0 0 0 -0 0</pose>
        <mass>0.01</mass>
        <inertia>
          <ixx>1e-06</ixx>
          <ixy>0</ixy>
          <ixz>0</ixz>
          <iyy>1e-06</iyy>
          <iyz>0</iyz>
          <izz>1e-06</izz>
        </inertia>
      </inertial>
      <collision name='qbhand_index_proximal_link_collision'>
        <pose frame=''>0 0 0 0 -0 0</pose>
        <geometry>
          <mesh>
            <scale>0.001 0.001 0.001</scale>
            <uri>model://qb_hand_description/meshes/ph_medium.stl</uri>
          </mesh>
        </geometry>
      </collision>
      <visual name='qbhand_index_proximal_link_visual'>
        <pose frame=''>0 0 0 0 -0 0</pose>
        <geometry>
          <mesh>
            <scale>0.001 0.001 0.001</scale>
            <uri>model://qb_hand_description/meshes/ph_medium.stl</uri>
          </mesh>
        </geometry>
      </visual>
    </link>
    <joint name='qbhand_index_proximal_virtual_joint' type='revolute'>
      <child>qbhand_index_proximal_link</child>
      <parent>qbhand_index_proximal_virtual_link</parent>
      <axis>
        <xyz>0.003981 2e-06 -0.999992</xyz>
        <limit>
          <lower>0</lower>
          <upper>0.785</upper>
          <effort>100</effort>
          <velocity>100</velocity>
        </limit>
        <dynamics>
          <damping>0</damping>
          <friction>0</friction>
          <spring_reference>0</spring_reference>
          <spring_stiffness>0</spring_stiffness>
        </dynamics>
        <use_parent_model_frame>1</use_parent_model_frame>
      </axis>
    </joint>
    <link name='qbhand_index_middle_virtual_link'>
      <pose frame=''>0.817693 0.367458 0.51887 -0.003981 1e-06 1.5716</pose>
      <inertial>
        <pose frame=''>0 0 0 0 -0 0</pose>
        <mass>0.01</mass>
        <inertia>
          <ixx>1e-08</ixx>
          <ixy>0</ixy>
          <ixz>0</ixz>
          <iyy>1e-08</iyy>
          <iyz>0</iyz>
          <izz>1e-08</izz>
        </inertia>
      </inertial>
    </link>
    <joint name='qbhand_index_middle_joint' type='revolute'>
      <child>qbhand_index_middle_virtual_link</child>
      <parent>qbhand_index_proximal_link</parent>
      <axis>
        <xyz>0.003981 2e-06 -0.999992</xyz>
        <limit>
          <lower>0</lower>
          <upper>0.785</upper>
          <effort>100</effort>
          <velocity>100</velocity>
        </limit>
        <dynamics>
          <damping>0</damping>
          <friction>0</friction>
          <spring_reference>0</spring_reference>
          <spring_stiffness>0</spring_stiffness>
        </dynamics>
        <use_parent_model_frame>1</use_parent_model_frame>
      </axis>
    </joint>
    <link name='qbhand_index_middle_link'>
      <pose frame=''>0.817682 0.380458 0.51887 -0.003981 1e-06 1.5716</pose>
      <inertial>
        <pose frame=''>0 0 0 0 -0 0</pose>
        <mass>0.01</mass>
        <inertia>
          <ixx>1e-06</ixx>
          <ixy>0</ixy>
          <ixz>0</ixz>
          <iyy>1e-06</iyy>
          <iyz>0</iyz>
          <izz>1e-06</izz>
        </inertia>
      </inertial>
      <collision name='qbhand_index_middle_link_collision'>
        <pose frame=''>0 0 0 0 -0 0</pose>
        <geometry>
          <mesh>
            <scale>0.001 0.001 0.001</scale>
            <uri>model://qb_hand_description/meshes/ph_small.stl</uri>
          </mesh>
        </geometry>
      </collision>
      <visual name='qbhand_index_middle_link_visual'>
        <pose frame=''>0 0 0 0 -0 0</pose>
        <geometry>
          <mesh>
            <scale>0.001 0.001 0.001</scale>
            <uri>model://qb_hand_description/meshes/ph_small.stl</uri>
          </mesh>
        </geometry>
      </visual>
    </link>
    <joint name='qbhand_index_middle_virtual_joint' type='revolute'>
      <child>qbhand_index_middle_link</child>
      <parent>qbhand_index_middle_virtual_link</parent>
      <axis>
        <xyz>0.003981 2e-06 -0.999992</xyz>
        <limit>
          <lower>0</lower>
          <upper>0.785</upper>
          <effort>100</effort>
          <velocity>100</velocity>
        </limit>
        <dynamics>
          <damping>0</damping>
          <friction>0</friction>
          <spring_reference>0</spring_reference>
          <spring_stiffness>0</spring_stiffness>
        </dynamics>
        <use_parent_model_frame>1</use_parent_model_frame>
      </axis>
    </joint>
    <link name='qbhand_index_distal_virtual_link'>
      <pose frame=''>0.817675 0.389458 0.51887 -0.003981 1e-06 1.5716</pose>
      <inertial>
        <pose frame=''>0 0 0 0 -0 0</pose>
        <mass>0.01</mass>
        <inertia>
          <ixx>1e-08</ixx>
          <ixy>0</ixy>
          <ixz>0</ixz>
          <iyy>1e-08</iyy>
          <iyz>0</iyz>
          <izz>1e-08</izz>
        </inertia>
      </inertial>
    </link>
    <joint name='qbhand_index_distal_joint' type='revolute'>
      <child>qbhand_index_distal_virtual_link</child>
      <parent>qbhand_index_middle_link</parent>
      <axis>
        <xyz>0.003981 2e-06 -0.999992</xyz>
        <limit>
          <lower>0</lower>
          <upper>0.785</upper>
          <effort>100</effort>
          <velocity>100</velocity>
        </limit>
        <dynamics>
          <damping>0</damping>
          <friction>0</friction>
          <spring_reference>0</spring_reference>
          <spring_stiffness>0</spring_stiffness>
        </dynamics>
        <use_parent_model_frame>1</use_parent_model_frame>
      </axis>
    </joint>
    <link name='qbhand_index_distal_link'>
      <pose frame=''>0.817665 0.402458 0.51887 -0.003981 1e-06 1.5716</pose>
      <inertial>
        <pose frame=''>0 0 0 0 -0 0</pose>
        <mass>0.01</mass>
        <inertia>
          <ixx>1e-06</ixx>
          <ixy>0</ixy>
          <ixz>0</ixz>
          <iyy>1e-06</iyy>
          <iyz>0</iyz>
          <izz>1e-06</izz>
        </inertia>
      </inertial>
      <collision name='qbhand_index_distal_link_collision'>
        <pose frame=''>0 0 0 0 -0 0</pose>
        <geometry>
          <mesh>
            <scale>0.001 0.001 0.001</scale>
            <uri>model://qb_hand_description/meshes/ph_distal.stl</uri>
          </mesh>
        </geometry>
      </collision>
      <visual name='qbhand_index_distal_link_visual'>
        <pose frame=''>0 0 0 0 -0 0</pose>
        <geometry>
          <mesh>
            <scale>0.001 0.001 0.001</scale>
            <uri>model://qb_hand_description/meshes/ph_distal.stl</uri>
          </mesh>
        </geometry>
      </visual>
    </link>
    <joint name='qbhand_index_distal_virtual_joint' type='revolute'>
      <child>qbhand_index_distal_link</child>
      <parent>qbhand_index_distal_virtual_link</parent>
      <axis>
        <xyz>0.003981 2e-06 -0.999992</xyz>
        <limit>
          <lower>0</lower>
          <upper>0.785</upper>
          <effort>100</effort>
          <velocity>100</velocity>
        </limit>
        <dynamics>
          <damping>0</damping>
          <friction>0</friction>
          <spring_reference>0</spring_reference>
          <spring_stiffness>0</spring_stiffness>
        </dynamics>
        <use_parent_model_frame>1</use_parent_model_frame>
      </axis>
    </joint>
    <link name='qbhand_little_knuckle_link'>
      <pose frame=''>0.817823 0.323411 0.458882 -2.89619 -1.56751 2.89699</pose>
      <inertial>
        <pose frame=''>0 0 0 0 -0 0</pose>
        <mass>0.01</mass>
        <inertia>
          <ixx>1e-06</ixx>
          <ixy>0</ixy>
          <ixz>0</ixz>
          <iyy>1e-06</iyy>
          <iyz>0</iyz>
          <izz>1e-06</izz>
        </inertia>
      </inertial>
      <collision name='qbhand_little_knuckle_link_collision'>
        <pose frame=''>0 0 0 0 -0 0</pose>
        <geometry>
          <mesh>
            <scale>0.001 0.001 0.001</scale>
            <uri>model://qb_hand_description/meshes/ph_knuckle.stl</uri>
          </mesh>
        </geometry>
      </collision>
      <visual name='qbhand_little_knuckle_link_visual'>
        <pose frame=''>0 0 0 0 -0 0</pose>
        <geometry>
          <mesh>
            <scale>0.001 0.001 0.001</scale>
            <uri>model://qb_hand_description/meshes/ph_knuckle.stl</uri>
          </mesh>
        </geometry>
      </visual>
    </link>
    <joint name='qbhand_little_knuckle_joint' type='revolute'>
      <child>qbhand_little_knuckle_link</child>
      <parent>wrist_3_link</parent>
      <axis>
        <xyz>0.999995 0.000799 0.003185</xyz>
        <limit>
          <lower>-0.524</lower>
          <upper>0.524</upper>
          <effort>100</effort>
          <velocity>100</velocity>
        </limit>
        <dynamics>
          <damping>0</damping>
          <friction>0</friction>
          <spring_reference>0</spring_reference>
          <spring_stiffness>0</spring_stiffness>
        </dynamics>
        <use_parent_model_frame>1</use_parent_model_frame>
      </axis>
    </joint>
    <link name='qbhand_little_proximal_virtual_link'>
      <pose frame=''>0.817816 0.332411 0.458874 -0.003981 1e-06 1.5716</pose>
      <inertial>
        <pose frame=''>0 0 0 0 -0 0</pose>
        <mass>0.01</mass>
        <inertia>
          <ixx>1e-08</ixx>
          <ixy>0</ixy>
          <ixz>0</ixz>
          <iyy>1e-08</iyy>
          <iyz>0</iyz>
          <izz>1e-08</izz>
        </inertia>
      </inertial>
    </link>
    <joint name='qbhand_little_proximal_joint' type='revolute'>
      <child>qbhand_little_proximal_virtual_link</child>
      <parent>qbhand_little_knuckle_link</parent>
      <axis>
        <xyz>0.003981 2e-06 -0.999992</xyz>
        <limit>
          <lower>0</lower>
          <upper>0.785</upper>
          <effort>100</effort>
          <velocity>100</velocity>
        </limit>
        <dynamics>
          <damping>0</damping>
          <friction>0</friction>
          <spring_reference>0</spring_reference>
          <spring_stiffness>0</spring_stiffness>
        </dynamics>
        <use_parent_model_frame>1</use_parent_model_frame>
      </axis>
    </joint>
    <link name='qbhand_little_proximal_link'>
      <pose frame=''>0.817806 0.345411 0.458874 -0.003981 1e-06 1.5716</pose>
      <inertial>
        <pose frame=''>0 0 0 0 -0 0</pose>
        <mass>0.01</mass>
        <inertia>
          <ixx>1e-06</ixx>
          <ixy>0</ixy>
          <ixz>0</ixz>
          <iyy>1e-06</iyy>
          <iyz>0</iyz>
          <izz>1e-06</izz>
        </inertia>
      </inertial>
      <collision name='qbhand_little_proximal_link_collision'>
        <pose frame=''>0 0 0 0 -0 0</pose>
        <geometry>
          <mesh>
            <scale>0.001 0.001 0.001</scale>
            <uri>model://qb_hand_description/meshes/ph_small.stl</uri>
          </mesh>
        </geometry>
      </collision>
      <visual name='qbhand_little_proximal_link_visual'>
        <pose frame=''>0 0 0 0 -0 0</pose>
        <geometry>
          <mesh>
            <scale>0.001 0.001 0.001</scale>
            <uri>model://qb_hand_description/meshes/ph_small.stl</uri>
          </mesh>
        </geometry>
      </visual>
    </link>
    <joint name='qbhand_little_proximal_virtual_joint' type='revolute'>
      <child>qbhand_little_proximal_link</child>
      <parent>qbhand_little_proximal_virtual_link</parent>
      <axis>
        <xyz>0.003981 2e-06 -0.999992</xyz>
        <limit>
          <lower>0</lower>
          <upper>0.785</upper>
          <effort>100</effort>
          <velocity>100</velocity>
        </limit>
        <dynamics>
          <damping>0</damping>
          <friction>0</friction>
          <spring_reference>0</spring_reference>
          <spring_stiffness>0</spring_stiffness>
        </dynamics>
        <use_parent_model_frame>1</use_parent_model_frame>
      </axis>
    </joint>
    <link name='qbhand_little_middle_virtual_link'>
      <pose frame=''>0.817799 0.354411 0.458874 -0.003981 1e-06 1.5716</pose>
      <inertial>
        <pose frame=''>0 0 0 0 -0 0</pose>
        <mass>0.01</mass>
        <inertia>
          <ixx>1e-08</ixx>
          <ixy>0</ixy>
          <ixz>0</ixz>
          <iyy>1e-08</iyy>
          <iyz>0</iyz>
          <izz>1e-08</izz>
        </inertia>
      </inertial>
    </link>
    <joint name='qbhand_little_middle_joint' type='revolute'>
      <child>qbhand_little_middle_virtual_link</child>
      <parent>qbhand_little_proximal_link</parent>
      <axis>
        <xyz>0.003981 2e-06 -0.999992</xyz>
        <limit>
          <lower>0</lower>
          <upper>0.785</upper>
          <effort>100</effort>
          <velocity>100</velocity>
        </limit>
        <dynamics>
          <damping>0</damping>
          <friction>0</friction>
          <spring_reference>0</spring_reference>
          <spring_stiffness>0</spring_stiffness>
        </dynamics>
        <use_parent_model_frame>1</use_parent_model_frame>
      </axis>
    </joint>
    <link name='qbhand_little_middle_link'>
      <pose frame=''>0.817788 0.367411 0.458874 -0.003981 1e-06 1.5716</pose>
      <inertial>
        <pose frame=''>0 0 0 0 -0 0</pose>
        <mass>0.01</mass>
        <inertia>
          <ixx>1e-06</ixx>
          <ixy>0</ixy>
          <ixz>0</ixz>
          <iyy>1e-06</iyy>
          <iyz>0</iyz>
          <izz>1e-06</izz>
        </inertia>
      </inertial>
      <collision name='qbhand_little_middle_link_collision'>
        <pose frame=''>0 0 0 0 -0 0</pose>
        <geometry>
          <mesh>
            <scale>0.001 0.001 0.001</scale>
            <uri>model://qb_hand_description/meshes/ph_small.stl</uri>
          </mesh>
        </geometry>
      </collision>
      <visual name='qbhand_little_middle_link_visual'>
        <pose frame=''>0 0 0 0 -0 0</pose>
        <geometry>
          <mesh>
            <scale>0.001 0.001 0.001</scale>
            <uri>model://qb_hand_description/meshes/ph_small.stl</uri>
          </mesh>
        </geometry>
      </visual>
    </link>
    <joint name='qbhand_little_middle_virtual_joint' type='revolute'>
      <child>qbhand_little_middle_link</child>
      <parent>qbhand_little_middle_virtual_link</parent>
      <axis>
        <xyz>0.003981 2e-06 -0.999992</xyz>
        <limit>
          <lower>0</lower>
          <upper>0.785</upper>
          <effort>100</effort>
          <velocity>100</velocity>
        </limit>
        <dynamics>
          <damping>0</damping>
          <friction>0</friction>
          <spring_reference>0</spring_reference>
          <spring_stiffness>0</spring_stiffness>
        </dynamics>
        <use_parent_model_frame>1</use_parent_model_frame>
      </axis>
    </joint>
    <link name='qbhand_little_distal_virtual_link'>
      <pose frame=''>0.817781 0.376411 0.458874 -0.003981 1e-06 1.5716</pose>
      <inertial>
        <pose frame=''>0 0 0 0 -0 0</pose>
        <mass>0.01</mass>
        <inertia>
          <ixx>1e-08</ixx>
          <ixy>0</ixy>
          <ixz>0</ixz>
          <iyy>1e-08</iyy>
          <iyz>0</iyz>
          <izz>1e-08</izz>
        </inertia>
      </inertial>
    </link>
    <joint name='qbhand_little_distal_joint' type='revolute'>
      <child>qbhand_little_distal_virtual_link</child>
      <parent>qbhand_little_middle_link</parent>
      <axis>
        <xyz>0.003981 2e-06 -0.999992</xyz>
        <limit>
          <lower>0</lower>
          <upper>0.785</upper>
          <effort>100</effort>
          <velocity>100</velocity>
        </limit>
        <dynamics>
          <damping>0</damping>
          <friction>0</friction>
          <spring_reference>0</spring_reference>
          <spring_stiffness>0</spring_stiffness>
        </dynamics>
        <use_parent_model_frame>1</use_parent_model_frame>
      </axis>
    </joint>
    <link name='qbhand_little_distal_link'>
      <pose frame=''>0.817771 0.389411 0.458874 -0.003981 1e-06 1.5716</pose>
      <inertial>
        <pose frame=''>0 0 0 0 -0 0</pose>
        <mass>0.01</mass>
        <inertia>
          <ixx>1e-06</ixx>
          <ixy>0</ixy>
          <ixz>0</ixz>
          <iyy>1e-06</iyy>
          <iyz>0</iyz>
          <izz>1e-06</izz>
        </inertia>
      </inertial>
      <collision name='qbhand_little_distal_link_collision'>
        <pose frame=''>0 0 0 0 -0 0</pose>
        <geometry>
          <mesh>
            <scale>0.001 0.001 0.001</scale>
            <uri>model://qb_hand_description/meshes/ph_distal.stl</uri>
          </mesh>
        </geometry>
      </collision>
      <visual name='qbhand_little_distal_link_visual'>
        <pose frame=''>0 0 0 0 -0 0</pose>
        <geometry>
          <mesh>
            <scale>0.001 0.001 0.001</scale>
            <uri>model://qb_hand_description/meshes/ph_distal.stl</uri>
          </mesh>
        </geometry>
      </visual>
    </link>
    <joint name='qbhand_little_distal_virtual_joint' type='revolute'>
      <child>qbhand_little_distal_link</child>
      <parent>qbhand_little_distal_virtual_link</parent>
      <axis>
        <xyz>0.003981 2e-06 -0.999992</xyz>
        <limit>
          <lower>0</lower>
          <upper>0.785</upper>
          <effort>100</effort>
          <velocity>100</velocity>
        </limit>
        <dynamics>
          <damping>0</damping>
          <friction>0</friction>
          <spring_reference>0</spring_reference>
          <spring_stiffness>0</spring_stiffness>
        </dynamics>
        <use_parent_model_frame>1</use_parent_model_frame>
      </axis>
    </joint>
    <link name='qbhand_middle_knuckle_link'>
      <pose frame=''>0.81775 0.335442 0.498872 -2.89619 -1.56751 2.89699</pose>
      <inertial>
        <pose frame=''>0 0 0 0 -0 0</pose>
        <mass>0.01</mass>
        <inertia>
          <ixx>1e-06</ixx>
          <ixy>0</ixy>
          <ixz>0</ixz>
          <iyy>1e-06</iyy>
          <iyz>0</iyz>
          <izz>1e-06</izz>
        </inertia>
      </inertial>
      <collision name='qbhand_middle_knuckle_link_collision'>
        <pose frame=''>0 0 0 0 -0 0</pose>
        <geometry>
          <mesh>
            <scale>0.001 0.001 0.001</scale>
            <uri>model://qb_hand_description/meshes/ph_knuckle.stl</uri>
          </mesh>
        </geometry>
      </collision>
      <visual name='qbhand_middle_knuckle_link_visual'>
        <pose frame=''>0 0 0 0 -0 0</pose>
        <geometry>
          <mesh>
            <scale>0.001 0.001 0.001</scale>
            <uri>model://qb_hand_description/meshes/ph_knuckle.stl</uri>
          </mesh>
        </geometry>
      </visual>
    </link>
    <joint name='qbhand_middle_knuckle_joint' type='revolute'>
      <child>qbhand_middle_knuckle_link</child>
      <parent>wrist_3_link</parent>
      <axis>
        <xyz>0.999995 0.000799 0.003185</xyz>
        <limit>
          <lower>-0.524</lower>
          <upper>0.524</upper>
          <effort>100</effort>
          <velocity>100</velocity>
        </limit>
        <dynamics>
          <damping>0</damping>
          <friction>0</friction>
          <spring_reference>0</spring_reference>
          <spring_stiffness>0</spring_stiffness>
        </dynamics>
        <use_parent_model_frame>1</use_parent_model_frame>
      </axis>
    </joint>
    <link name='qbhand_middle_proximal_virtual_link'>
      <pose frame=''>0.817743 0.344442 0.498865 -0.003981 1e-06 1.5716</pose>
      <inertial>
        <pose frame=''>0 0 0 0 -0 0</pose>
        <mass>0.01</mass>
        <inertia>
          <ixx>1e-08</ixx>
          <ixy>0</ixy>
          <ixz>0</ixz>
          <iyy>1e-08</iyy>
          <iyz>0</iyz>
          <izz>1e-08</izz>
        </inertia>
      </inertial>
    </link>
    <joint name='qbhand_middle_proximal_joint' type='revolute'>
      <child>qbhand_middle_proximal_virtual_link</child>
      <parent>qbhand_middle_knuckle_link</parent>
      <axis>
        <xyz>0.003981 2e-06 -0.999992</xyz>
        <limit>
          <lower>0</lower>
          <upper>0.785</upper>
          <effort>100</effort>
          <velocity>100</velocity>
        </limit>
        <dynamics>
          <damping>0</damping>
          <friction>0</friction>
          <spring_reference>0</spring_reference>
          <spring_stiffness>0</spring_stiffness>
        </dynamics>
        <use_parent_model_frame>1</use_parent_model_frame>
      </axis>
    </joint>
    <link name='qbhand_middle_proximal_link'>
      <pose frame=''>0.817732 0.357442 0.498865 -0.003981 1e-06 1.5716</pose>
      <inertial>
        <pose frame=''>0 0 0 0 -0 0</pose>
        <mass>0.01</mass>
        <inertia>
          <ixx>1e-06</ixx>
          <ixy>0</ixy>
          <ixz>0</ixz>
          <iyy>1e-06</iyy>
          <iyz>0</iyz>
          <izz>1e-06</izz>
        </inertia>
      </inertial>
      <collision name='qbhand_middle_proximal_link_collision'>
        <pose frame=''>0 0 0 0 -0 0</pose>
        <geometry>
          <mesh>
            <scale>0.001 0.001 0.001</scale>
            <uri>model://qb_hand_description/meshes/ph_medium.stl</uri>
          </mesh>
        </geometry>
      </collision>
      <visual name='qbhand_middle_proximal_link_visual'>
        <pose frame=''>0 0 0 0 -0 0</pose>
        <geometry>
          <mesh>
            <scale>0.001 0.001 0.001</scale>
            <uri>model://qb_hand_description/meshes/ph_medium.stl</uri>
          </mesh>
        </geometry>
      </visual>
    </link>
    <joint name='qbhand_middle_proximal_virtual_joint' type='revolute'>
      <child>qbhand_middle_proximal_link</child>
      <parent>qbhand_middle_proximal_virtual_link</parent>
      <axis>
        <xyz>0.003981 2e-06 -0.999992</xyz>
        <limit>
          <lower>0</lower>
          <upper>0.785</upper>
          <effort>100</effort>
          <velocity>100</velocity>
        </limit>
        <dynamics>
          <damping>0</damping>
          <friction>0</friction>
          <spring_reference>0</spring_reference>
          <spring_stiffness>0</spring_stiffness>
        </dynamics>
        <use_parent_model_frame>1</use_parent_model_frame>
      </axis>
    </joint>
    <link name='qbhand_middle_middle_virtual_link'>
      <pose frame=''>0.817719 0.374442 0.498865 -0.003981 1e-06 1.5716</pose>
      <inertial>
        <pose frame=''>0 0 0 0 -0 0</pose>
        <mass>0.01</mass>
        <inertia>
          <ixx>1e-08</ixx>
          <ixy>0</ixy>
          <ixz>0</ixz>
          <iyy>1e-08</iyy>
          <iyz>0</iyz>
          <izz>1e-08</izz>
        </inertia>
      </inertial>
    </link>
    <joint name='qbhand_middle_middle_joint' type='revolute'>
      <child>qbhand_middle_middle_virtual_link</child>
      <parent>qbhand_middle_proximal_link</parent>
      <axis>
        <xyz>0.003981 2e-06 -0.999992</xyz>
        <limit>
          <lower>0</lower>
          <upper>0.785</upper>
          <effort>100</effort>
          <velocity>100</velocity>
        </limit>
        <dynamics>
          <damping>0</damping>
          <friction>0</friction>
          <spring_reference>0</spring_reference>
          <spring_stiffness>0</spring_stiffness>
        </dynamics>
        <use_parent_model_frame>1</use_parent_model_frame>
      </axis>
    </joint>
    <link name='qbhand_middle_middle_link'>
      <pose frame=''>0.817709 0.387442 0.498865 -0.003981 1e-06 1.5716</pose>
      <inertial>
        <pose frame=''>0 0 0 0 -0 0</pose>
        <mass>0.01</mass>
        <inertia>
          <ixx>1e-06</ixx>
          <ixy>0</ixy>
          <ixz>0</ixz>
          <iyy>1e-06</iyy>
          <iyz>0</iyz>
          <izz>1e-06</izz>
        </inertia>
      </inertial>
      <collision name='qbhand_middle_middle_link_collision'>
        <pose frame=''>0 0 0 0 -0 0</pose>
        <geometry>
          <mesh>
            <scale>0.001 0.001 0.001</scale>
            <uri>model://qb_hand_description/meshes/ph_small.stl</uri>
          </mesh>
        </geometry>
      </collision>
      <visual name='qbhand_middle_middle_link_visual'>
        <pose frame=''>0 0 0 0 -0 0</pose>
        <geometry>
          <mesh>
            <scale>0.001 0.001 0.001</scale>
            <uri>model://qb_hand_description/meshes/ph_small.stl</uri>
          </mesh>
        </geometry>
      </visual>
    </link>
    <joint name='qbhand_middle_middle_virtual_joint' type='revolute'>
      <child>qbhand_middle_middle_link</child>
      <parent>qbhand_middle_middle_virtual_link</parent>
      <axis>
        <xyz>0.003981 2e-06 -0.999992</xyz>
        <limit>
          <lower>0</lower>
          <upper>0.785</upper>
          <effort>100</effort>
          <velocity>100</velocity>
        </limit>
        <dynamics>
          <damping>0</damping>
          <friction>0</friction>
          <spring_reference>0</spring_reference>
          <spring_stiffness>0</spring_stiffness>
        </dynamics>
        <use_parent_model_frame>1</use_parent_model_frame>
      </axis>
    </joint>
    <link name='qbhand_middle_distal_virtual_link'>
      <pose frame=''>0.817701 0.396442 0.498865 -0.003981 1e-06 1.5716</pose>
      <inertial>
        <pose frame=''>0 0 0 0 -0 0</pose>
        <mass>0.01</mass>
        <inertia>
          <ixx>1e-08</ixx>
          <ixy>0</ixy>
          <ixz>0</ixz>
          <iyy>1e-08</iyy>
          <iyz>0</iyz>
          <izz>1e-08</izz>
        </inertia>
      </inertial>
    </link>
    <joint name='qbhand_middle_distal_joint' type='revolute'>
      <child>qbhand_middle_distal_virtual_link</child>
      <parent>qbhand_middle_middle_link</parent>
      <axis>
        <xyz>0.003981 2e-06 -0.999992</xyz>
        <limit>
          <lower>0</lower>
          <upper>0.785</upper>
          <effort>100</effort>
          <velocity>100</velocity>
        </limit>
        <dynamics>
          <damping>0</damping>
          <friction>0</friction>
          <spring_reference>0</spring_reference>
          <spring_stiffness>0</spring_stiffness>
        </dynamics>
        <use_parent_model_frame>1</use_parent_model_frame>
      </axis>
    </joint>
    <link name='qbhand_middle_distal_link'>
      <pose frame=''>0.817691 0.409442 0.498865 -0.003981 1e-06 1.5716</pose>
      <inertial>
        <pose frame=''>0 0 0 0 -0 0</pose>
        <mass>0.01</mass>
        <inertia>
          <ixx>1e-06</ixx>
          <ixy>0</ixy>
          <ixz>0</ixz>
          <iyy>1e-06</iyy>
          <iyz>0</iyz>
          <izz>1e-06</izz>
        </inertia>
      </inertial>
      <collision name='qbhand_middle_distal_link_collision'>
        <pose frame=''>0 0 0 0 -0 0</pose>
        <geometry>
          <mesh>
            <scale>0.001 0.001 0.001</scale>
            <uri>model://qb_hand_description/meshes/ph_distal.stl</uri>
          </mesh>
        </geometry>
      </collision>
      <visual name='qbhand_middle_distal_link_visual'>
        <pose frame=''>0 0 0 0 -0 0</pose>
        <geometry>
          <mesh>
            <scale>0.001 0.001 0.001</scale>
            <uri>model://qb_hand_description/meshes/ph_distal.stl</uri>
          </mesh>
        </geometry>
      </visual>
    </link>
    <joint name='qbhand_middle_distal_virtual_joint' type='revolute'>
      <child>qbhand_middle_distal_link</child>
      <parent>qbhand_middle_distal_virtual_link</parent>
      <axis>
        <xyz>0.003981 2e-06 -0.999992</xyz>
        <limit>
          <lower>0</lower>
          <upper>0.785</upper>
          <effort>100</effort>
          <velocity>100</velocity>
        </limit>
        <dynamics>
          <damping>0</damping>
          <friction>0</friction>
          <spring_reference>0</spring_reference>
          <spring_stiffness>0</spring_stiffness>
        </dynamics>
        <use_parent_model_frame>1</use_parent_model_frame>
      </axis>
    </joint>
    <link name='qbhand_ring_knuckle_link'>
      <pose frame=''>0.817787 0.328426 0.478878 -2.89619 -1.56751 2.89699</pose>
      <inertial>
        <pose frame=''>0 0 0 0 -0 0</pose>
        <mass>0.01</mass>
        <inertia>
          <ixx>1e-06</ixx>
          <ixy>0</ixy>
          <ixz>0</ixz>
          <iyy>1e-06</iyy>
          <iyz>0</iyz>
          <izz>1e-06</izz>
        </inertia>
      </inertial>
      <collision name='qbhand_ring_knuckle_link_collision'>
        <pose frame=''>0 0 0 0 -0 0</pose>
        <geometry>
          <mesh>
            <scale>0.001 0.001 0.001</scale>
            <uri>model://qb_hand_description/meshes/ph_knuckle.stl</uri>
          </mesh>
        </geometry>
      </collision>
      <visual name='qbhand_ring_knuckle_link_visual'>
        <pose frame=''>0 0 0 0 -0 0</pose>
        <geometry>
          <mesh>
            <scale>0.001 0.001 0.001</scale>
            <uri>model://qb_hand_description/meshes/ph_knuckle.stl</uri>
          </mesh>
        </geometry>
      </visual>
    </link>
    <joint name='qbhand_ring_knuckle_joint' type='revolute'>
      <child>qbhand_ring_knuckle_link</child>
      <parent>wrist_3_link</parent>
      <axis>
        <xyz>0.999995 0.000799 0.003185</xyz>
        <limit>
          <lower>-0.524</lower>
          <upper>0.524</upper>
          <effort>100</effort>
          <velocity>100</velocity>
        </limit>
        <dynamics>
          <damping>0</damping>
          <friction>0</friction>
          <spring_reference>0</spring_reference>
          <spring_stiffness>0</spring_stiffness>
        </dynamics>
        <use_parent_model_frame>1</use_parent_model_frame>
      </axis>
    </joint>
    <link name='qbhand_ring_proximal_virtual_link'>
      <pose frame=''>0.81778 0.337426 0.47887 -0.003981 1e-06 1.5716</pose>
      <inertial>
        <pose frame=''>0 0 0 0 -0 0</pose>
        <mass>0.01</mass>
        <inertia>
          <ixx>1e-08</ixx>
          <ixy>0</ixy>
          <ixz>0</ixz>
          <iyy>1e-08</iyy>
          <iyz>0</iyz>
          <izz>1e-08</izz>
        </inertia>
      </inertial>
    </link>
    <joint name='qbhand_ring_proximal_joint' type='revolute'>
      <child>qbhand_ring_proximal_virtual_link</child>
      <parent>qbhand_ring_knuckle_link</parent>
      <axis>
        <xyz>0.003981 2e-06 -0.999992</xyz>
        <limit>
          <lower>0</lower>
          <upper>0.785</upper>
          <effort>100</effort>
          <velocity>100</velocity>
        </limit>
        <dynamics>
          <damping>0</damping>
          <friction>0</friction>
          <spring_reference>0</spring_reference>
          <spring_stiffness>0</spring_stiffness>
        </dynamics>
        <use_parent_model_frame>1</use_parent_model_frame>
      </axis>
    </joint>
    <link name='qbhand_ring_proximal_link'>
      <pose frame=''>0.81777 0.350426 0.47887 -0.003981 1e-06 1.5716</pose>
      <inertial>
        <pose frame=''>0 0 0 0 -0 0</pose>
        <mass>0.01</mass>
        <inertia>
          <ixx>1e-06</ixx>
          <ixy>0</ixy>
          <ixz>0</ixz>
          <iyy>1e-06</iyy>
          <iyz>0</iyz>
          <izz>1e-06</izz>
        </inertia>
      </inertial>
      <collision name='qbhand_ring_proximal_link_collision'>
        <pose frame=''>0 0 0 0 -0 0</pose>
        <geometry>
          <mesh>
            <scale>0.001 0.001 0.001</scale>
            <uri>model://qb_hand_description/meshes/ph_medium.stl</uri>
          </mesh>
        </geometry>
      </collision>
      <visual name='qbhand_ring_proximal_link_visual'>
        <pose frame=''>0 0 0 0 -0 0</pose>
        <geometry>
          <mesh>
            <scale>0.001 0.001 0.001</scale>
            <uri>model://qb_hand_description/meshes/ph_medium.stl</uri>
          </mesh>
        </geometry>
      </visual>
    </link>
    <joint name='qbhand_ring_proximal_virtual_joint' type='revolute'>
      <child>qbhand_ring_proximal_link</child>
      <parent>qbhand_ring_proximal_virtual_link</parent>
      <axis>
        <xyz>0.003981 2e-06 -0.999992</xyz>
        <limit>
          <lower>0</lower>
          <upper>0.785</upper>
          <effort>100</effort>
          <velocity>100</velocity>
        </limit>
        <dynamics>
          <damping>0</damping>
          <friction>0</friction>
          <spring_reference>0</spring_reference>
          <spring_stiffness>0</spring_stiffness>
        </dynamics>
        <use_parent_model_frame>1</use_parent_model_frame>
      </axis>
    </joint>
    <link name='qbhand_ring_middle_virtual_link'>
      <pose frame=''>0.817756 0.367426 0.47887 -0.003981 1e-06 1.5716</pose>
      <inertial>
        <pose frame=''>0 0 0 0 -0 0</pose>
        <mass>0.01</mass>
        <inertia>
          <ixx>1e-08</ixx>
          <ixy>0</ixy>
          <ixz>0</ixz>
          <iyy>1e-08</iyy>
          <iyz>0</iyz>
          <izz>1e-08</izz>
        </inertia>
      </inertial>
    </link>
    <joint name='qbhand_ring_middle_joint' type='revolute'>
      <child>qbhand_ring_middle_virtual_link</child>
      <parent>qbhand_ring_proximal_link</parent>
      <axis>
        <xyz>0.003981 2e-06 -0.999992</xyz>
        <limit>
          <lower>0</lower>
          <upper>0.785</upper>
          <effort>100</effort>
          <velocity>100</velocity>
        </limit>
        <dynamics>
          <damping>0</damping>
          <friction>0</friction>
          <spring_reference>0</spring_reference>
          <spring_stiffness>0</spring_stiffness>
        </dynamics>
        <use_parent_model_frame>1</use_parent_model_frame>
      </axis>
    </joint>
    <link name='qbhand_ring_middle_link'>
      <pose frame=''>0.817746 0.380426 0.47887 -0.003981 1e-06 1.5716</pose>
      <inertial>
        <pose frame=''>0 0 0 0 -0 0</pose>
        <mass>0.01</mass>
        <inertia>
          <ixx>1e-06</ixx>
          <ixy>0</ixy>
          <ixz>0</ixz>
          <iyy>1e-06</iyy>
          <iyz>0</iyz>
          <izz>1e-06</izz>
        </inertia>
      </inertial>
      <collision name='qbhand_ring_middle_link_collision'>
        <pose frame=''>0 0 0 0 -0 0</pose>
        <geometry>
          <mesh>
            <scale>0.001 0.001 0.001</scale>
            <uri>model://qb_hand_description/meshes/ph_small.stl</uri>
          </mesh>
        </geometry>
      </collision>
      <visual name='qbhand_ring_middle_link_visual'>
        <pose frame=''>0 0 0 0 -0 0</pose>
        <geometry>
          <mesh>
            <scale>0.001 0.001 0.001</scale>
            <uri>model://qb_hand_description/meshes/ph_small.stl</uri>
          </mesh>
        </geometry>
      </visual>
    </link>
    <joint name='qbhand_ring_middle_virtual_joint' type='revolute'>
      <child>qbhand_ring_middle_link</child>
      <parent>qbhand_ring_middle_virtual_link</parent>
      <axis>
        <xyz>0.003981 2e-06 -0.999992</xyz>
        <limit>
          <lower>0</lower>
          <upper>0.785</upper>
          <effort>100</effort>
          <velocity>100</velocity>
        </limit>
        <dynamics>
          <damping>0</damping>
          <friction>0</friction>
          <spring_reference>0</spring_reference>
          <spring_stiffness>0</spring_stiffness>
        </dynamics>
        <use_parent_model_frame>1</use_parent_model_frame>
      </axis>
    </joint>
    <link name='qbhand_ring_distal_virtual_link'>
      <pose frame=''>0.817739 0.389426 0.47887 -0.003981 1e-06 1.5716</pose>
      <inertial>
        <pose frame=''>0 0 0 0 -0 0</pose>
        <mass>0.01</mass>
        <inertia>
          <ixx>1e-08</ixx>
          <ixy>0</ixy>
          <ixz>0</ixz>
          <iyy>1e-08</iyy>
          <iyz>0</iyz>
          <izz>1e-08</izz>
        </inertia>
      </inertial>
    </link>
    <joint name='qbhand_ring_distal_joint' type='revolute'>
      <child>qbhand_ring_distal_virtual_link</child>
      <parent>qbhand_ring_middle_link</parent>
      <axis>
        <xyz>0.003981 2e-06 -0.999992</xyz>
        <limit>
          <lower>0</lower>
          <upper>0.785</upper>
          <effort>100</effort>
          <velocity>100</velocity>
        </limit>
        <dynamics>
          <damping>0</damping>
          <friction>0</friction>
          <spring_reference>0</spring_reference>
          <spring_stiffness>0</spring_stiffness>
        </dynamics>
        <use_parent_model_frame>1</use_parent_model_frame>
      </axis>
    </joint>
    <link name='qbhand_ring_distal_link'>
      <pose frame=''>0.817728 0.402426 0.47887 -0.003981 1e-06 1.5716</pose>
      <inertial>
        <pose frame=''>0 0 0 0 -0 0</pose>
        <mass>0.01</mass>
        <inertia>
          <ixx>1e-06</ixx>
          <ixy>0</ixy>
          <ixz>0</ixz>
          <iyy>1e-06</iyy>
          <iyz>0</iyz>
          <izz>1e-06</izz>
        </inertia>
      </inertial>
      <collision name='qbhand_ring_distal_link_collision'>
        <pose frame=''>0 0 0 0 -0 0</pose>
        <geometry>
          <mesh>
            <scale>0.001 0.001 0.001</scale>
            <uri>model://qb_hand_description/meshes/ph_distal.stl</uri>
          </mesh>
        </geometry>
      </collision>
      <visual name='qbhand_ring_distal_link_visual'>
        <pose frame=''>0 0 0 0 -0 0</pose>
        <geometry>
          <mesh>
            <scale>0.001 0.001 0.001</scale>
            <uri>model://qb_hand_description/meshes/ph_distal.stl</uri>
          </mesh>
        </geometry>
      </visual>
    </link>
    <joint name='qbhand_ring_distal_virtual_joint' type='revolute'>
      <child>qbhand_ring_distal_link</child>
      <parent>qbhand_ring_distal_virtual_link</parent>
      <axis>
        <xyz>0.003981 2e-06 -0.999992</xyz>
        <limit>
          <lower>0</lower>
          <upper>0.785</upper>
          <effort>100</effort>
          <velocity>100</velocity>
        </limit>
        <dynamics>
          <damping>0</damping>
          <friction>0</friction>
          <spring_reference>0</spring_reference>
          <spring_stiffness>0</spring_stiffness>
        </dynamics>
        <use_parent_model_frame>1</use_parent_model_frame>
      </axis>
    </joint>
    <link name='qbhand_tendon_virtual_link'>
      <pose frame=''>0.83175 0.335454 0.498894 -0.464444 1.56902 -0.463647</pose>
      <inertial>
        <pose frame=''>0 0 0 0 -0 0</pose>
        <mass>0.01</mass>
        <inertia>
          <ixx>1e-08</ixx>
          <ixy>0</ixy>
          <ixz>0</ixz>
          <iyy>1e-08</iyy>
          <iyz>0</iyz>
          <izz>1e-08</izz>
        </inertia>
      </inertial>
    </link>
    <joint name='qbhand_synergy_joint' type='revolute'>
      <child>qbhand_tendon_virtual_link</child>
      <parent>wrist_3_link</parent>
      <axis>
        <xyz>0.999998 0.000798 0.001592</xyz>
        <limit>
          <lower>0</lower>
          <upper>1</upper>
          <effort>100</effort>
          <velocity>100</velocity>
        </limit>
        <dynamics>
          <damping>0</damping>
          <friction>0</friction>
          <spring_reference>0</spring_reference>
          <spring_stiffness>0</spring_stiffness>
        </dynamics>
        <use_parent_model_frame>1</use_parent_model_frame>
      </axis>
    </joint>
    <link name='qbhand_thumb_knuckle_link'>
      <pose frame=''>0.829715 0.291987 0.542426 -1.32619 -1.56751 2.89699</pose>
      <inertial>
        <pose frame=''>0 0 0 0 -0 0</pose>
        <mass>0.01</mass>
        <inertia>
          <ixx>1e-06</ixx>
          <ixy>0</ixy>
          <ixz>0</ixz>
          <iyy>1e-06</iyy>
          <iyz>0</iyz>
          <izz>1e-06</izz>
        </inertia>
      </inertial>
      <collision name='qbhand_thumb_knuckle_link_collision'>
        <pose frame=''>0 0 0 0 -0 0</pose>
        <geometry>
          <mesh>
            <scale>0.001 0.001 0.001</scale>
            <uri>model://qb_hand_description/meshes/ph_thumb_l.stl</uri>
          </mesh>
        </geometry>
      </collision>
      <visual name='qbhand_thumb_knuckle_link_visual'>
        <pose frame=''>0 0 0 0 -0 0</pose>
        <geometry>
          <mesh>
            <scale>0.001 0.001 0.001</scale>
            <uri>model://qb_hand_description/meshes/ph_thumb_l.stl</uri>
          </mesh>
        </geometry>
      </visual>
    </link>
    <joint name='qbhand_thumb_knuckle_joint' type='revolute'>
      <child>qbhand_thumb_knuckle_link</child>
      <parent>wrist_3_link</parent>
      <axis>
        <xyz>-0 1 -0.000795</xyz>
        <limit>
          <lower>0</lower>
          <upper>1.571</upper>
          <effort>100</effort>
          <velocity>100</velocity>
        </limit>
        <dynamics>
          <damping>0</damping>
          <friction>0</friction>
          <spring_reference>0</spring_reference>
          <spring_stiffness>0</spring_stiffness>
        </dynamics>
        <use_parent_model_frame>1</use_parent_model_frame>
      </axis>
    </joint>
    <link name='qbhand_thumb_proximal_virtual_link'>
      <pose frame=''>0.833634 0.289507 0.56794 -0.176192 -1.56751 2.89699</pose>
      <inertial>
        <pose frame=''>0 0 0 0 -0 0</pose>
        <mass>0.01</mass>
        <inertia>
          <ixx>1e-08</ixx>
          <ixy>0</ixy>
          <ixz>0</ixz>
          <iyy>1e-08</iyy>
          <iyz>0</iyz>
          <izz>1e-08</izz>
        </inertia>
      </inertial>
    </link>
    <joint name='qbhand_thumb_proximal_joint' type='revolute'>
      <child>qbhand_thumb_proximal_virtual_link</child>
      <parent>qbhand_thumb_knuckle_link</parent>
      <axis>
        <xyz>-0.912759 0.408485 -0.003232</xyz>
        <limit>
          <lower>0</lower>
          <upper>0.785</upper>
          <effort>100</effort>
          <velocity>100</velocity>
        </limit>
        <dynamics>
          <damping>0</damping>
          <friction>0</friction>
          <spring_reference>0</spring_reference>
          <spring_stiffness>0</spring_stiffness>
        </dynamics>
        <use_parent_model_frame>1</use_parent_model_frame>
      </axis>
    </joint>
    <link name='qbhand_thumb_proximal_link'>
      <pose frame=''>0.833593 0.289517 0.58094 -0.176192 -1.56751 2.89699</pose>
      <inertial>
        <pose frame=''>0 0 0 0 -0 0</pose>
        <mass>0.01</mass>
        <inertia>
          <ixx>1e-06</ixx>
          <ixy>0</ixy>
          <ixz>0</ixz>
          <iyy>1e-06</iyy>
          <iyz>0</iyz>
          <izz>1e-06</izz>
        </inertia>
      </inertial>
      <collision name='qbhand_thumb_proximal_link_collision'>
        <pose frame=''>0 0 0 0 -0 0</pose>
        <geometry>
          <mesh>
            <scale>0.001 0.001 0.001</scale>
            <uri>model://qb_hand_description/meshes/ph_small.stl</uri>
          </mesh>
        </geometry>
      </collision>
      <visual name='qbhand_thumb_proximal_link_visual'>
        <pose frame=''>0 0 0 0 -0 0</pose>
        <geometry>
          <mesh>
            <scale>0.001 0.001 0.001</scale>
            <uri>model://qb_hand_description/meshes/ph_small.stl</uri>
          </mesh>
        </geometry>
      </visual>
    </link>
    <joint name='qbhand_thumb_proximal_virtual_joint' type='revolute'>
      <child>qbhand_thumb_proximal_link</child>
      <parent>qbhand_thumb_proximal_virtual_link</parent>
      <axis>
        <xyz>-0.912759 0.408485 -0.003232</xyz>
        <limit>
          <lower>0</lower>
          <upper>0.785</upper>
          <effort>100</effort>
          <velocity>100</velocity>
        </limit>
        <dynamics>
          <damping>0</damping>
          <friction>0</friction>
          <spring_reference>0</spring_reference>
          <spring_stiffness>0</spring_stiffness>
        </dynamics>
        <use_parent_model_frame>1</use_parent_model_frame>
      </axis>
    </joint>
    <link name='qbhand_thumb_distal_virtual_link'>
      <pose frame=''>0.833564 0.289524 0.58994 -0.176192 -1.56751 2.89699</pose>
      <inertial>
        <pose frame=''>0 0 0 0 -0 0</pose>
        <mass>0.01</mass>
        <inertia>
          <ixx>1e-08</ixx>
          <ixy>0</ixy>
          <ixz>0</ixz>
          <iyy>1e-08</iyy>
          <iyz>0</iyz>
          <izz>1e-08</izz>
        </inertia>
      </inertial>
    </link>
    <joint name='qbhand_thumb_distal_joint' type='revolute'>
      <child>qbhand_thumb_distal_virtual_link</child>
      <parent>qbhand_thumb_proximal_link</parent>
      <axis>
        <xyz>-0.912759 0.408485 -0.003232</xyz>
        <limit>
          <lower>0</lower>
          <upper>0.785</upper>
          <effort>100</effort>
          <velocity>100</velocity>
        </limit>
        <dynamics>
          <damping>0</damping>
          <friction>0</friction>
          <spring_reference>0</spring_reference>
          <spring_stiffness>0</spring_stiffness>
        </dynamics>
        <use_parent_model_frame>1</use_parent_model_frame>
      </axis>
    </joint>
    <link name='qbhand_thumb_distal_link'>
      <pose frame=''>0.833523 0.289535 0.60294 -0.176192 -1.56751 2.89699</pose>
      <inertial>
        <pose frame=''>0 0 0 0 -0 0</pose>
        <mass>0.01</mass>
        <inertia>
          <ixx>1e-06</ixx>
          <ixy>0</ixy>
          <ixz>0</ixz>
          <iyy>1e-06</iyy>
          <iyz>0</iyz>
          <izz>1e-06</izz>
        </inertia>
      </inertial>
      <collision name='qbhand_thumb_distal_link_collision'>
        <pose frame=''>0 0 0 0 -0 0</pose>
        <geometry>
          <mesh>
            <scale>0.001 0.001 0.001</scale>
            <uri>model://qb_hand_description/meshes/ph_distal.stl</uri>
          </mesh>
        </geometry>
      </collision>
      <visual name='qbhand_thumb_distal_link_visual'>
        <pose frame=''>0 0 0 0 -0 0</pose>
        <geometry>
          <mesh>
            <scale>0.001 0.001 0.001</scale>
            <uri>model://qb_hand_description/meshes/ph_distal.stl</uri>
          </mesh>
        </geometry>
      </visual>
    </link>
    <joint name='qbhand_thumb_distal_virtual_joint' type='revolute'>
      <child>qbhand_thumb_distal_link</child>
      <parent>qbhand_thumb_distal_virtual_link</parent>
      <axis>
        <xyz>-0.912759 0.408485 -0.003232</xyz>
        <limit>
          <lower>0</lower>
          <upper>0.785</upper>
          <effort>100</effort>
          <velocity>100</velocity>
        </limit>
        <dynamics>
          <damping>0</damping>
          <friction>0</friction>
          <spring_reference>0</spring_reference>
          <spring_stiffness>0</spring_stiffness>
        </dynamics>
        <use_parent_model_frame>1</use_parent_model_frame>
      </axis>
    </joint>
    <static>0</static>
    <plugin name='ros_control' filename='libgazebo_ros_control.so'/>
  </model>
</sdf>
